2025-08-22 14:26:18 - uvicorn.error - ERROR - Traceback (most recent call last):
  File "C:\Users\z0054unn\AppData\Local\Programs\Python\Python313\Lib\asyncio\runners.py", line 118, in run
    return self._loop.run_until_complete(task)
           ~~~~~~~~~~~~~~~~~~~~~~~~~~~~~^^^^^^
  File "C:\Users\z0054unn\AppData\Local\Programs\Python\Python313\Lib\asyncio\base_events.py", line 725, in run_until_complete
    return future.result()
           ~~~~~~~~~~~~~^^
asyncio.exceptions.CancelledError

During handling of the above exception, another exception occurred:

Traceback (most recent call last):
  File "C:\Users\z0054unn\AppData\Local\Programs\Python\Python313\Lib\asyncio\runners.py", line 195, in run
    return runner.run(main)
           ~~~~~~~~~~^^^^^^
  File "C:\Users\z0054unn\AppData\Local\Programs\Python\Python313\Lib\asyncio\runners.py", line 123, in run
    raise KeyboardInterrupt()
KeyboardInterrupt

During handling of the above exception, another exception occurred:

Traceback (most recent call last):
  File "C:\Users\z0054unn\AppData\Local\Programs\Python\Python313\Lib\site-packages\starlette\routing.py", line 699, in lifespan
    await receive()
  File "C:\Users\z0054unn\AppData\Local\Programs\Python\Python313\Lib\site-packages\uvicorn\lifespan\on.py", line 137, in receive
    return await self.receive_queue.get()
           ^^^^^^^^^^^^^^^^^^^^^^^^^^^^^^
  File "C:\Users\z0054unn\AppData\Local\Programs\Python\Python313\Lib\asyncio\queues.py", line 186, in get
    await getter
asyncio.exceptions.CancelledError

