2025-08-22 14:20:11 - root - INFO - 服务器日志系统初始化完成，日志文件: C:\Users\z0054unn\Documents\Siemens-GitLab\Third-party\third-party-clearance\logs\server_20250822_14h20m11s.log
2025-08-22 14:20:11 - uvicorn.error - INFO - Started server process [30460]
2025-08-22 14:20:11 - uvicorn.error - INFO - Waiting for application startup.
2025-08-22 14:20:11 - back_end.server - INFO - FastAPI应用启动
2025-08-22 14:20:11 - uvicorn.error - INFO - Application startup complete.
2025-08-22 14:20:11 - uvicorn.error - ERROR - Traceback (most recent call last):
  File "C:\Users\z0054unn\AppData\Local\Programs\Python\Python313\Lib\asyncio\runners.py", line 118, in run
    return self._loop.run_until_complete(task)
           ~~~~~~~~~~~~~~~~~~~~~~~~~~~~~^^^^^^
  File "C:\Users\z0054unn\AppData\Local\Programs\Python\Python313\Lib\asyncio\base_events.py", line 725, in run_until_complete
    return future.result()
           ~~~~~~~~~~~~~^^
asyncio.exceptions.CancelledError

During handling of the above exception, another exception occurred:

Traceback (most recent call last):
  File "C:\Users\z0054unn\AppData\Local\Programs\Python\Python313\Lib\asyncio\runners.py", line 195, in run
    return runner.run(main)
           ~~~~~~~~~~^^^^^^
  File "C:\Users\z0054unn\AppData\Local\Programs\Python\Python313\Lib\asyncio\runners.py", line 123, in run
    raise KeyboardInterrupt()
KeyboardInterrupt

During handling of the above exception, another exception occurred:

Traceback (most recent call last):
  File "C:\Users\z0054unn\AppData\Local\Programs\Python\Python313\Lib\site-packages\starlette\routing.py", line 699, in lifespan
    await receive()
  File "C:\Users\z0054unn\AppData\Local\Programs\Python\Python313\Lib\site-packages\uvicorn\lifespan\on.py", line 137, in receive
    return await self.receive_queue.get()
           ^^^^^^^^^^^^^^^^^^^^^^^^^^^^^^
  File "C:\Users\z0054unn\AppData\Local\Programs\Python\Python313\Lib\asyncio\queues.py", line 186, in get
    await getter
asyncio.exceptions.CancelledError

