2025-08-18 16:29:38 - back_end.server - ERROR - Error during chat: unhashable type: 'dict'
Traceback (most recent call last):
  File "C:\Users\z0054unn\Documents\Siemens-GitLab\Third-party\third-party-clearance\back_end\server.py", line 220, in chat
    run_report(updated_shared)
    ~~~~~~~~~~^^^^^^^^^^^^^^^^
  File "C:\Users\z0054unn\Documents\Siemens-GitLab\Third-party\third-party-clearance\main.py", line 13, in run_report
    flow.run(shared)
    ~~~~~~~~^^^^^^^^
  File "C:\Users\z0054unn\AppData\Local\Programs\Python\Python313\Lib\site-packages\pocketflow\__init__.py", line 16, in run
    return self._run(shared)
           ~~~~~~~~~^^^^^^^^
  File "C:\Users\z0054unn\AppData\Local\Programs\Python\Python313\Lib\site-packages\pocketflow\__init__.py", line 50, in _run
    def _run(self,shared): p=self.prep(shared); o=self._orch(shared); return self.post(shared,p,o)
                                                  ~~~~~~~~~~^^^^^^^^
  File "C:\Users\z0054unn\AppData\Local\Programs\Python\Python313\Lib\site-packages\pocketflow\__init__.py", line 48, in _orch
    while curr: curr.set_params(p); last_action=curr._run(shared); curr=copy.copy(self.get_next_node(curr,last_action))
                                                                                  ~~~~~~~~~~~~~~~~~~^^^^^^^^^^^^^^^^^^
  File "C:\Users\z0054unn\AppData\Local\Programs\Python\Python313\Lib\site-packages\pocketflow\__init__.py", line 43, in get_next_node
    nxt=curr.successors.get(action or "default")
TypeError: unhashable type: 'dict'
2025-08-18 16:29:38 - utils.tools - ERROR - Error CHAT_ERROR: Error during contract analysis: unhashable type: 'dict'
